Workbook
Name 입력조건: #REF!
Name 입력조건: #REF!
Name 입력조건: #REF!
Name 입력조건: #REF!
Name 입력조건: #REF!
Name 입력조건: #REF!
Name 입력조건: #REF!
Name 입력조건: #REF!
Name 입력조건: #REF!
Name 입력조건: #REF!
Name 입력조건: #REF!
Name 입력조건: #REF!
Name 입력조건: #REF!
Name 입력조건: #REF!
Name 입력조건: #REF!
Name 입력조건: #REF!
Name 입력조건: #REF!
Name 입력조건: #REF!
Name 입력조건: #REF!
Name 판정기준: #REF!
Name 판정기준: #REF!
Name 판정기준: #REF!
Name 판정기준: #REF!
Name 판정기준: #REF!
Name 판정기준: #REF!
Name 판정기준: #REF!
Name 판정기준: #REF!
Name 판정기준: #REF!
Name 판정기준: #REF!
Name 판정기준: #REF!
Name 판정기준: #REF!
Name 판정기준: #REF!
Name 판정기준: #REF!
Name 판정기준: #REF!
Name 판정기준: #REF!
Name 판정기준: #REF!
Name 판정기준: #REF!
Name 판정기준: #REF!
Name 항목: #REF!
Name 항목: #REF!
Name 항목: #REF!
Name 항목: #REF!
Name 항목: #REF!
Name 항목: #REF!
Name 항목: #REF!
Name 항목: #REF!
Name 항목: #REF!
Name 항목: #REF!
Name 항목: #REF!
Name 항목: #REF!
Name 항목: #REF!
Name 항목: #REF!
Name 항목: #REF!
Name 항목: #REF!
Name 항목: #REF!
Name 항목: #REF!
Name 항목: #REF!

Sheet HISTORY
A1: TestCase 변경 HISTORY | I1: 품명: BLTN_CAM | J1: Product Name: BLTN_CAM
I2: 제정일자 2021- - | J2: Date of enactment 2021- -
A3: Rev | B3: 구분 | C3: 시트 | D3: TC ID | E3: 항목 | F3: 내용 | G3: 적용 일자 | H3: 작성자 | I3: 자동화 동기화 여부 | J3: Whether to synchronize automation
A4: 1910_01 | B4: 최초작성 시작
A5: 1905_01 | B5: 추가 | C5: 주행 중 녹화 기능 | D5: OWD_048 | E5: [DCM 출력 확인] : 작동 상태 확인 | F5: DCM 테스트 케이스 추가 | G5: 45807 | H5: 이수희 | I5: O | J5: O
B6: 추가 | D6: OWD_049 | E6: [DCM 출력 확인] : 영향성 확인 | F6: DCM 테스트 케이스 추가 | I6: O | J6: O
B7: 추가 | C7: HU 연동 기능 | D7: HU_007 | E7: [카메라 각도 설정] 후방카메라 실시간 화면 | F7: 후방 카메라 각도 설정 시 DCM 적용 여부 추가 (STEP13) | I7: O | J7: O
B8: 추가 | D8: HU_007 | E8: [카메라 각도 설정] 후방카메라 실시간 화면 | F8: B+ 리셋 후 DCM 영상 출력 화면 반복 확인 추가 (STEP15) | I8: O | J8: O
B9: 수정 | D9: HU_027 -> 008 | E9: [주차 모션 감지 녹화 설정] : HU_BLTN_CAM_01_00ms | F9: 중복 T/C ID 제거 후 HU_008 변경 | I9: O | J9: O
B10: 추가 | C10: 비기능 외 | D10: ETC_025 | E10: [CANFD 메시지 별 시그널 출력여부 확인] - 7 | F10: DCM 신규 시그널 추가 | I10: O | J10: O
B11: 추가 | D11: ETC_026 | E11: [CANFD 메시지 별 시그널 출력여부 확인] - 8 | F11: DCM 신규 시그널 추가 | I11: O | J11: O
B12: 추가 | D12: ETC_027 | E12: [CANFD 메시지 별 시그널 출력여부 확인] - 9 | F12: DCM 신규 시그널 추가 | I12: O | J12: O
B13: 추가 | D13: ETC_028 | E13: [CANFD 메시지 별 시그널 출력여부 확인] - 10 | F13: DCM 신규 시그널 추가 | I13: O | J13: O
A14: 1906_01 | B14: 추가 | C14: 차량정보 저장기능 | D14: INF_011 | E14: [차량 주행데이터 저장] : 방향지시등 | F14: 전자바디E2.0 , E3.0 아키텍처 적용 차량 방향지시등 신호 구분 및 추가(전자바디 E3.0 아키텍처 적용 차량 TC 추가) | G14: 45819 | H14: 이수희 | I14: O | J14: O
A15: 2207_01 | B15: 추가 | C15: 보조배터리 연동기능 | D15: BAT_055 | E15: [M-LBM 적용 차종] 녹화 동작 사양 -1 | F15: MBLM SOC값에 따른 주차 녹화 사양 TC추가 | G15: 45846 | H15: 이수희 | I15: O | J15: O
B16: 수정 | C16: 보조배터리 연동기능 | D16: BAT_056 | E16: [M-LBM 적용 차종] 녹화 동작 사양 -2 | F16: MLBM SOC값에 따른 모션 녹화 동작 사양 수정 | I16: O | J16: O
B17: 추가 | C17: 보조배터리 연동기능 | D17: BAT_057 | E17: [M-LBM 적용 차종] 녹화 동작 사양 -3 | F17: MLBM 적용 차종 주차 녹화 종료 조건 TC 추가 | I17: O | J17: O
B18: 추가 | C18: 보조배터리 연동기능 | D18: BAT_058 | E18: [M-LBM 적용 차종] 녹화 동작 사양 -4 | F18: MLBM 적용 차종 모션 녹화 종료 조건 TC 추가 | I18: O | J18: O
A19: 2207_02 | B19: 수정 | C19: 차량정보 저장기능 | D19: INF_009 | E19: [주행정보 OSD기록 정합성 확인] : 주행/주차 수동 이벤트 | F19: 주차 중 수동 이벤트 녹화 동작 시 주행정보 사양에서 기어 "P" 단 표시 삭제 (스탬핑 정보 사양에서 기어 미표시) | G19: 45853 | H19: 이수희 | I19: O | J19: O
A20: 2207_03 | B20: 추가 | C20: 표시 관련 서비스 | D20: IND_002 | E20: [CW 팝업 요청] BLTN_CAM_PopUp_Req | F20: 타임랩스 녹화 불가 알림 TC 추가 | G20: 45853 | H20: 이수희 | I20: O | J20: O
A21: 2207_04 | B21: 추가 | C21: 저장메모리 및 파일관리 | D21: MEM_052 | E21: Write 불가 상태 SD카드 사용시 알림 확인 | F21: Write 불가능한 불량 SD카드 이용시 알림 TC 추가 | G21: 45853 | H21: 이수희 | I21: O | J21: O
A22: 2207_05 | B22: 추가 | C22: 진단서비스(1) | D22: DIA_040 | E22: SID 22 [$A221] 주차 녹화 정보 취득 | F22: 신규 진단 서비스 A221(주차 녹화 정보 취득) 추가 | G22: 45860 | H22: 이수희 | I22: O | J22: O
A23: 2208_01 | B23: 추가 | C23: 차량정보 저장기능 | D23: INF_019 | E23: [주행정보 OSD기록 정합성 확인] : 퍼포먼스 | F23: 변속 모드 별 표시 방식 변경, Not dectect 시 사양 변경 | G23: 45874 | H23: 이수희 | I23: O | J23: O
A24: 2208_02 | B24: 추가 | C24: 저장메모리 및 파일관리 | D24: MEM_038 | E24: [SD카드 사용자 조건] (1) | F24: PC에서 썸네일만 삭제 후 SD카드 장착 시 썸네일 생성 확인 TC 추가 | G24: 45877 | H24: 이수희 | I24: O | J24: O
B25: 수정 | C25: 주차 후 녹화 기능 | D25: OWP_021 | E25: [모션 감지 범위 설정 확인] 주차 중 모션감지 범위 설정 Lv2 | F25: 유럽향 모션 감지 범위 설정 확인값 변경 BLTN_CAM_RanSet_PMDR=0x3 → 0x2 | G25: 45894 | H25: 이수희 | I25: O | J25: O
A26: 2208_03 | B26: 수정 | C26: HU 연동기능 | D26: HU_043 | E26: [사용자프로필 설정] | F26: 수행절차, 기대값 수정 | G26: 45896 | H26: 이수희 | I26: O | J26: O
C27: 커넥티드 관련 서비스 | D27: CCS_011 | E27: [영상 저장 사양 확인] : CCS 파일 사양 | F27: 수행절차 수정 저장 경로 변경 /tmp → /mnt/data/video)
B28: 추가 | C28: HU 연동 기능 | D28: HU_036 | E28: [언어 및 지역연동] | F28: BLTN_CAM_DistributeInfo 신호 추가
C29: 주행 중 녹화 기능 | D29: OWD_050 | E29: [주행 중 수동 이벤트 스위치 녹화] 터치 스위치 고장 정보 신호 | F29: MAR_SoftKeyEnable / MAR_SoftKeySystemFailStatus 신호 확인 추가
C30: 주차 후 녹화 기능 | D30: OWP_017 | E30: [주차중 모션 감지 녹화] | F30: BLTN_CAM_PMD_Count 신호 확인 추가
C31: 주행 중 녹화 기능 | D31: OWD_051 | E31: [타임랩스 녹화] (8) : 터치 스위치 고장 정보 신호 | F31: TML_SoftKeyEnable / TML_SoftKeySystemFailStatus 신호 확인 추가
C32: HU 연동 기능 | D32: HU_047 | E32: [ssfs 통신] ssfs 통신 방향 | F32: HU_SSHFS_StrictHostKeyCheck1 신호 확인 추가
C33: 모바일 앱 연동기능 | D33: APP_020 | E33: [스트리밍 기능 설정] | F33: BLTN_CAM_RecSet_STRM 신호 확인 추가
A34: 2309_01 | B34: 추가 | C34: 주차 후 녹화 기능 | D34: OWP_025 | E34: 카메라 탈거 및 장착 영향성 | F34: 서스펜드 모드 상태에서 전/후방 카메라 탈착 | G34: 45912 | H34: 이수희 | I34: O | J34: O
F35: 네트워크 상태에 따른 전/ 후방 카메라 탈착 영향성 확인
F36: 서스펜드 모드 진입 시점에 전/후방 카메라 탈착
F37: 주차 모션 대기 상태에서 전/후방 카메라 탈착
F38: 전/후방 카메라 탈착으로 인한 WAKE UP 상태에서 ccs동작
A39: 2309_02 | B39: 추가 | C39: 동작 성능 | D39: PER_044 | E39: 녹화 기능 확인 [악의 조건] | F39: 주차 녹화 동작 리셋 확인 | G39: 45922 | H39: 이수희 | I39: O | J39: O
F40: 주행 녹화 동작 리셋 확인 | I40: O | J40: O
...

Sheet 표지
D1: 기능 검증 보고서 | J1: 작 성 | L1: 검 토 | N1: 승 인
A4: 문서 번호 | C4: 2.5세대 플랫폼 23.25.A0.11.03 기능 검증 | H4: 검증 목적 | J4: 플랫폼 개정 사양에 대한 기능 정합성 및 동작 유효성 검증
A5: 품 명 | C5: 빌트인캠 2.5세대 | H5: 기 간 | J5: 2026
A6: 참조 스펙 | C6: 01_System_Spec_BLTN_CAM_v2_4(20260115).docx | H6: 담 당
A7: 플랫폼 Ver. | C7: 23.25.A0.11.03
A8: CAN DB Ver. | C8: 20230523_STD_DB_CAR_2021_HS_B2_v23.05.01.dbc | H8: LIN DB Ver. | J8: P-LBM_LIN_DB_A_01.ldf
B9: 차종 | C9: 이벤트 | D9: HU 타입 | E9: HU Ver. | G9: 주차 전원 | H9: H/W Ver. | J9: 진단/OTA | M9: 이더넷 속도
A10: 1 | B10: JK1 PE RUS | D10: ccIC | E10: JX1PE.KOR.ccNC.000.605.230831 | H10: 1.00
A11: 2
A15: No | B15: 항목 | G15: 총 TC 수 | H15: 실행 TC 수 | I15: 결과 | K15: 판정 | L15: 개선 검증 | M15: 비고
I16: 적합 | J16: 부적합
A17: 1 | B17: 녹화 제어 | C17: 주행 중 녹화 관련 기능 | G17: =COUNT((#REF!)) -> 0 | H17: =SUM(I17:J17) -> #REF! | I17: =COUNTIF(#REF!,"Pass") -> #REF! | J17: =COUNTIF(#REF!,"Fail") -> #REF! | K17: Fail | L17: Pass | M17: 23.25.A0.11.03 #2 개선확인
A18: 2 | C18: 주차 녹화 관련 기능 | G18: =COUNT('주차 후 녹화 기능'!H:H) -> 258 | H18: =SUM(I18:J18) -> 0 | I18: =COUNTIF('주차 후 녹화 기능'!K:K,"Pass") -> 0 | J18: =COUNTIF('주차 후 녹화 기능'!K:K,"Fail") -> 0 | K18: Pass | L18: -
A19: 3 | B19: 연동 제어 | C19: 헤드 유닛 연동 기능 | G19: =COUNT((#REF!)) -> 0 | H19: =SUM(I19:J19) -> #REF! | I19: =COUNTIF(#REF!,"Pass") -> #REF! | J19: =COUNTIF(#REF!,"Fail") -> #REF! | K19: Pass | L19: -
A20: 4 | C20: 보조배터리 소모 전력 및 연동 기능 | G20: =COUNT((#REF!)) -> 0 | H20: =SUM(I20:J20) -> #REF! | I20: =COUNTIF(#REF!,"Pass") -> #REF! | J20: =COUNTIF(#REF!,"Fail") -> #REF! | K20: Pass | L20: -
A21: 5 | C21: WiFi 연결 및 모바일 앱 연동 기능 | G21: =COUNT((#REF!)) -> 0 | H21: =SUM(I21:J21) -> #REF! | I21: =COUNTIF(#REF!,"Pass") -> #REF! | J21: =COUNTIF(#REF!,"Fail") -> #REF! | K21: Pass | L21: -
A22: 6 | C22: DCM 연동 기능 | G22: =COUNT((#REF!)) -> 0 | H22: =SUM(I22:J22) -> #REF! | I22: =COUNTIF(#REF!,"Pass") -> #REF! | J22: =COUNTIF('주차 후 녹화 기능'!K:K,"Fail") -> 0 | K22: Pass | L22: -
A23: 7 | B23: 서비스 제어 | C23: 빌트인캠 상태 정보 표시 관련 기능 | G23: =COUNT((#REF!)) -> 0 | H23: =SUM(I23:J23) -> #REF! | I23: =COUNTIF(#REF!,"Pass") -> #REF! | J23: =COUNTIF(#REF!,"Fail") -> #REF! | K23: Pass | L23: -
A24: 8 | C24: 커넥티드 관련 빌트인캠 상태 알림 관련 기능 | G24: =COUNT((#REF!)) -> 0 | H24: =SUM(I24:J24) -> #REF! | I24: =COUNTIF(#REF!,"Pass") -> #REF! | J24: =COUNTIF(#REF!,"Fail") -> #REF! | K24: Pass | L24: -
A25: 9 | B25: 기타 제어 | C25: 주행 중 차량정보(메타데이터) 저장 기능 | G25: =COUNT((#REF!)) -> 0 | H25: =SUM(I25:J25) -> #REF! | I25: =COUNTIF(#REF!,"Pass") -> #REF! | J25: =COUNTIF(#REF!,"Fail") -> #REF! | K25: Pass | L25: -
A26: 10 | C26: 녹화 영상 및 소리 재생 및 편집 기능 | G26: =COUNT((#REF!)) -> 0 | H26: =SUM(I26:J26) -> #REF! | I26: =COUNTIF(#REF!,"Pass") -> #REF! | J26: =COUNTIF(#REF!,"Fail") -> #REF! | K26: Pass | L26: -
A27: 11 | C27: 녹화 파일 정보 및 SD 카드 사양 확인 | G27: =COUNT((#REF!)) -> 0 | H27: =SUM(I27:J27) -> #REF! | I27: =COUNTIF(#REF!,"Pass") -> #REF! | J27: =COUNTIF(#REF!,"Fail") -> #REF! | K27: Pass | L27: -
A28: 12 | C28: 실시간 영상 출력, 차량 모드, 업데이트 외 | G28: =COUNT((#REF!)) -> 0 | H28: =SUM(I28:J28) -> #REF! | I28: =COUNTIF(#REF!,"Pass") -> #REF! | J28: =COUNTIF(#REF!,"Fail") -> #REF! | K28: Pass | L28: -
A29: 13 | B29: 동작 성능 | C29: 동작 성능 | G29: =COUNT('동작 성능'!H:H) -> 202 | H29: =SUM(I29:J29) -> 0 | I29: =COUNTIF('동작 성능'!K:K,"Pass") -> 0 | J29: =COUNTIF('동작 성능'!K:K,"Fail") -> 0 | K29: Pass | L29: -
A30: 14 | C30: 전기적 성능, 네트워크 동작 사양, 통신 정합성 외 | G30: =COUNT((#REF!)) -> 0 | H30: =SUM(I30:J30) -> #REF! | I30: =COUNTIF(#REF!,"Pass") -> #REF! | J30: =COUNTIF(#REF!,"Fail") -> #REF! | K30: Pass | L30: -
A31: 15 | B31: 진단 서비스 | C31: 고장진단, I/O Control 및 ERT기능 | G31: =COUNT((#REF!)) -> 0 | H31: =SUM(I31:J31) -> #REF! | I31: =COUNTIF(#REF!,"Pass") -> #REF! | J31: =COUNTIF(#REF!,"Fail") -> #REF! | K31: Pass | L31: -
A32: 16 | C32: ECU Identification 외 | G32: =COUNT((#REF!)) -> 0 | H32: =SUM(I32:J32) -> #REF! | I32: =COUNTIF(#REF!,"Pass") -> #REF! | J32: =COUNTIF(#REF!,"Fail") -> #REF! | K32: Pass | L32: -
A33: 17 | C33: Session, Communication Control 외 | G33: =COUNT((#REF!)) -> 0 | H33: =SUM(I33:J33) -> #REF! | I33: =COUNTIF(#REF!,"Pass") -> #REF! | J33: =COUNTIF(#REF!,"Fail") -> #REF! | K33: Pass | L33: -
A34: Total | G34: =SUM(G17:G33) -> 460 | H34: =SUM(H17:H33) -> #REF! | I34: =SUM(I17:I33) -> #REF! | J34: =SUM(J17:J33) -> #REF! | K34: Pass
A35: ※ 유럽 BLTN_CAM_RecSet_OWD = 0x1(OFF) : FRS 설정동작 이후 초기화 시 녹화설정 기본값은 OFF

Sheet TestCases
A1: ID, Name을 조합하여 {ID}: {Name}으로 Title 자동 입력
A2: ID | B2: Name | C2: Test method | D2: TC design method | E2: SyR ID | F2: Description | G2: Preconfition | H2: Step | I2: Test Procedure | J2: Expected Result
A3: 1. 공백, 언더바, 하이픈 연속 2번 사용 불가 2. 괄호 내 공백("( ", " )") 사용 불가 3. "," 사용 불가 | B3: 1. 공백, 언더바, 하이픈 연속 2번 사용 불가 2. 괄호 내 공백("( ", " )") 사용 불가 3. "," 사용 불가 | C3: - | D3: - | E3: 폴라리온 내 SyR Title 입력 (title기준은 A1셀 참고) | F3: Step 별로 구분되어 있는 경우 하나의 셀로 병합 되므로 구분자 추가 필요 | G3: Step 별로 구분되어 있는 경우 하나의 셀로 병합 되므로 구분자 추가 필요 | H3: - | I3: - | J3: -

Sheet 주행 중 녹화 기능
A1: {="OWD_"&TEXT(MAX(IFERROR(--MID($A$2:$A$4931,5,3),0)),"000")} -> OWD_051 | E1: English Translation | F1: English Translation | G1: English Translation | I1: English Translation | J1: English Translation
A2: ID | B2: SyR ID | C2: Test method | D2: TC design method | E2: Name | F2: Description | G2: Preconfition | H2: Step | I2: Test Procedure | J2: Expect Result | K2: Result | L2: Measure Value | M2: Remarks | O2: Manual (Basic) | P2: Automation (Basic) | Q2: Automation Applied | R2: Specification Category
A3: OWD_001 | B3: SyR-FR-058,SyR-FR-059,SyR-FR-060 | C3: Requirement-based test | D3: Requirements Analysis | E3: [Continuous recording while driving] - (1) | F3: Check initial values ​​for continuous driving recording settings | G3: ▪ Built-in Cam: Booted successfully ▪ Front/Rear Camera: Recognized by the system ▪ SD Card: Original installed and ready to store data ▪ DCM/CCU/CW: Connected and recognized by the system ▪ Vehicle Power: KEY ON ▪ Vehicle Voltage: 12V | H3: 1 | I3: ▪ ICUPowerAutoCutModesta = 0x0 (Factory mode) → 0x2 (Customer mode) ▪ Transmit CF_AVN_BLTN_CAM_USMReset = 0x1 (Built-in Cam USM Reset) signal - Check initial values | J3: ▪ BLTN_CAM_RecSet_OWD = 0x1(OFF) : Initial value to OFF after changing from Factory mode to Customer mode | O3: O | P3: X | Q3: O
H4: 2 | I4: ▪ Turn on Parking Continuous Recording Setting (to check the initial value after FRS setting operation) ▪ Transmit CF_AVN_BLTN_CAM_USMReset = 0x1 (Built-in Cam USM Reset) signal | J4: BLTN_CAM_RecSet_OWD = 0x2(ON) : The default recording setting is ON when initializing after FRS setup operation. | O4: X | P4: X | Q4: X
A5: OWD_002 | B5: SyR-FR-001,SyR-IF-001,SyR-NFR-001,SEQ006 | C5: Requirement-based test | D5: Requirements Analysis | E5: [Continuous Recording While Driving] - (2) | F5: Confirmation that continuous driving recording is not working in BLTN_CAM mode | G5: ▪ Built-in Cam: Booted successfully ▪ Front/Rear Camera: Recognized by the system ▪ SD Card: Original installed and ready to save ▪ DCM/CCU/CW: Connected and recognized by the system ▪ Vehicle Power: KEY ON ▪ Vehicle Voltage: 12V ▪ Settings: Continuous Driving Recording / Driving Event Settings ON | H5: 1 | I5: ▪ Enter Built-in Cam Mode ▪ Check Recording Status Signal | J5: ▪ BLTN_CAM_RecSta_OWD = 0x0(OFF) | O5: O | P5: O | Q5: O
H6: 2 | I6: ▪ Check front/rear camera indicator | J6: ▪ F/R-CAM_INDI = OFF | O6: O | P6: X | Q6: X
H7: 3 | I7: ▪ Check EVENT_SW_INDI | J7: ▪ EVENT_SW_INDI = OFF | O7: O | P7: O | Q7: O
F8: Confirmed non-operation of continuous driving recording in Engineer mode | H8: 4 | I8: ▪ Enter Engineer Mode ▪ Check Recording Status Signal | J8: ▪ BLTN_CAM_RecSta_OWD = 0x0(OFF) | O8: X | P8: O | Q8: O
H9: 5 | I9: ▪ Check front/rear camera indicator | J9: ▪ F/R-CAM_INDI = OFF | O9: X | P9: X | Q9: X
H10: 6 | I10: ▪ Check EVENT_SW_INDI | J10: ▪ EVENT_SW_INDI = OFF | O10: X | P10: O | Q10: O
F11: Check recording operation in AVN mode (IGN power) | H11: 7 | I11: ▪ Switch AVN screen ▪ Check recording status signal | J11: ▪ BLTN_CAM_RecSta_OWD = 0x1(Recoreding) ※ The signal delay between the actual recording time and the actual recording time will be 1 second. | O11: O | P11: O | Q11: O
H12: 8 | I12: ▪ Check the time taken to start recording (In Built-in Cam mode, the time is measured by the stopwatch as soon as the HOME button is pressed, and recorded as the time captured in the recording file) | J12: ▪ Recording starts within 4 seconds of exiting Built-in Cam mode | O12: O | P12: X | Q12: X
H13: 9 | I13: ▪ Check front/rear camera indicator | J13: ▪ F/R-CAM_INDI = Blink - Blink Frequency: 0.5Hz(Duty : 50%) | O13: O | P13: X | Q13: X
H14: 10 | I14: ▪ Check EVENT_SW_INDI | J14: ▪ EVENT_SW_INDI = ON | O14: O | P14: O | Q14: O
F15: Check recording operation in AVN mode (ACC power) | H15: 11 | I15: ▪ Switch AVN screen ▪ Check recording status signal | J15: ▪ BLTN_CAM_RecSta_OWD = 0x1(Recoreding) | O15: O | P15: O | Q15: O
H16: 12 | I16: ▪ Check the time taken to start recording (In Built-in Cam mode, the time is measured by the stopwatch as soon as the HOME button is pressed, and recorded as the time captured in the recording file) | J16: ▪ Recording starts within 4 seconds of exiting Built-in Cam mode | O16: O | P16: X | Q16: X
H17: 13 | I17: ▪ Check front/rear camera indicator | J17: ▪ F/R-CAM_INDI = Flash - Flash Frequency: 0.5Hz (Flash Duty: 50%) | O17: O | P17: X | Q17: X
H18: 14 | I18: ▪ Check EVENT_SW_INDI | J18: ▪ EVENT_SW_INDI = ON | O18: O | P18: O | Q18: O
A19: OWD_003 | B19: SyR-FR-001,SyR-IF-001,SyR-NFR-001,SyR-IF-064,SyR-CON-036,SyR-FR-099,SyR-CON-037,SyR-FR-101,SyR-FR-102,SyR-FR-104,SyR-FR-105,SyR-CON-038,SEQ006 | C19: Requirement-based test | D19: Requirements Analysis | E19: [Continuous Recording While Driving] - (3) | F19: Confirm recording file creation (3 minutes) - Create 3 1-minute recording files | G19: ▪ Built-in Cam: Boot complete ▪ Front/Rear Camera: System recognized correctly ▪ SD Card: Original installed and ready to save ▪ DCM/CCU/CW: System connected and recognized correctly ▪ Vehicle Power: KEY ON ▪ Vehicle Voltage: 12V ▪ Settings: Continuous Driving Recording / Driving Event Settings ON ▪ AVN Mode | H19: 1 | I19: ▪ 3-minute standby ▪ Enter Built-in Cam main screen ▪ [Always on while driving] Check storage box | J19: ▪ Thumbnail and video name (date and time) should be verified correctly. ▪ Three videos (front + rear) (60 sec) should be combined and displayed as a single group. | O19: X | P19: X | Q19: X
H20: 2 | I20: ▪ Play generated recording file | J20: ▪ There should be no issues with video tearing, black screens, noise, or video color. | O20: X | P20: X | Q20: X
F21: Check recording file specifications | H21: 3 | I21: ▪ Check the frame rate of the generated recording file on the PC | J21: ▪ Video saving/playback frame rate 30 FPS | O21: O | P21: X | Q21: X
H22: 4 | I22: ▪ Check the resolution of the generated recording file on the PC | J22: ▪ Resolution 2980*1440 (QHD) | O22: O | P22: X | Q22: X
H23: 5 | I23: ▪ Check audio on the generated recording file on the PC | J23: ▪ Voice recording available | O23: X | P23: X | Q23: X
H24: 6 | I24: ▪ Check horizontal flip of the generated recording file on the PC | J24: ▪ No horizontal flip of the video | O24: O | P24: X | Q24: X
F25: Check for abnormalities while maintaining driving recording for 5 minutes or more. | H25: 7 | I25: ▪ Driving recording in progress ▪ Monitoring BLTN_CAM_RecSet_OWD signal for 5 minutes | J25: ▪ BLTN_CAM_RecSet_OWD signal remains ON (Will not turn OFF at the time of recording file creation) | O25: O | P25: X | Q25: X
F26: Check that the continuous driving recording setting is OFF. | H26: 8 | I26: ▪ Built-in Cam Main Screen ▪ [Settings] - [Recording] - [Recording While Driving] - Continuous Recording Setting OFF | J26: ▪ BLTN_CAM_RecSet_OWD = 0x1(OFF) | O26: X | P26: O | Q26: O
F27: Confirmation that continuous driving recording does not operate when recording setting is OFF | H27: 9 | I27: ▪ [Settings] - [Recording] - [Recording While Driving] - Turn Off Continuous Driving Recording / Turn Off Driving Event Settings ▪ Switch AVN Screen ▪ Check Recording Status Signal | J27: ▪ BLTN_CAM_RecSta_OWD = 0x0(OFF) | O27: X | P27: O | Q27: O
H28: 10 | I28: ▪ Check front/rear camera indicator | J28: ▪ F/R-CAM_INDI = OFF | O28: X | P28: X | Q28: X
F29: Separate group index when date changes during recording | H29: 11 | I29: ▪ [Settings] - [Recording] - [Recording While Driving] - Continuous Driving Recording ON / Driving Event Settings ON ▪ [System Settings] - Change System Time to 23:58:00 ▪ Driving recording starts at 23:58:30 ▪ After 3 minutes, 3 recording files are created, then check the driving recording video list | J29: ▪ Created as 2 recording groups - 23:58:30 ~ 00:00:30 - 00:00:30 ~ 00:01:30 | O29: X | P29: X | Q29: X
A30: OWD_004 | B30: SyR-FR-001,SyR-IF-001,SyR-NFR-001SyR-IF-064,SyR-CON-036,SyR-FR-099,SyR-CON-037,SyR-FR-101,SyR-FR-102,SyR-FR-104SyR-CON-038,SEQ006 | C30: Requirement-based test | D30: Requirements Analysis | E30: [Continuous Recording While Driving] - (4) | F30: Check the recording file after entering parking recording. | G30: ▪ Built-in Cam: Boot complete ▪ Front/Rear Camera: System recognized correctly ▪ SD Card: Original installed and ready to save ▪ DCM/CCU/CW: System connected and recognized correctly ▪ Vehicle Power: KEY ON ▪ Vehicle Voltage: 12V ▪ Settings: Continuous Driving Recording / Driving Event Settings ON ▪ AVN Mode | H30: 1 | I30: ▪ Turn KEY OFF to enter Parking Recording (Records for 10 seconds) ▪ Turn ACC and IGN ON to start Driving Recording (Records for 10 seconds) ▪ Repeat the above 5 times, then check the [Always Recording While Driving] box | J30: ▪ Thumbnail and video name (date and time) should be verified correctly | O30: O | P30: X | Q30: X
H31: 2 | I31: ▪ Play generated recording file | J31: ▪ There should be no issues with video tearing, black screens, noise, or video color. | O31: O | P31: X | Q31: X
F32: Check whether recording is performed after repeatedly turning IGN ON/OFF | H32: 3 | I32: ▪ Repeat ACC & IGN ON/OFF quickly 20 times ▪ ACC & IGN ON ▪ Check recording status signal | J32: ▪ BLTN_CAM_RecSet_OWD = 0x2(ON) | O32: O | P32: X | Q32: O
H33: 4 | I33: ▪ Check front/rear camera indicator | J33: ▪ F/R-CAM_INDI = Flash - Flash Frequency: 0.5Hz (Flash Duty: 50%) | O33: O | P33: X | Q33: X
H34: 5 | I34: ▪ Check EVENT_SW_INDI | J34: ▪ EVENT_SW_INDI = ON | O34: O | P34: X | Q34: O
A35: OWD_033 | B35: SyR-FR-063,SyR-FR-001,SyR-IF-001,SyR-NFR-001 | C35: Requirement-based test | D35: Requirements Analysis | E35: (European Version) One-time setting for continuous driving recording | F35: Confirmation that continuous driving recording is not performed after entering parking recording. | G35: ▪ Built-in Cam: Boot complete ▪ Front/Rear Camera: System recognized correctly ▪ SD Card: Original installed and ready to save ▪ DCM/CCU/CW: System connected and recognized correctly ▪ Vehicle Power: KEY ON ▪ Vehicle Voltage: 12V ▪ Settings: Continuous Driving Recording / Driving Event Settings ON ▪ AVN Mode | H35: 1 | I35: ▪ Driving recording for 10 seconds with ACC and IGN ON ▪ Enter parking recording by turning KEY OFF (10-second parking recording) ▪ Driving recording does not proceed when ACC and IGN are ON | J35: ▪ BLTN_CAM_RecSet_OWD = 0x1(OFF) ▪ BLTN_CAM_RecSta_OWD = 0x0(OFF) | O35: X | P35: X | Q35: O
F36: Check whether recording is performed after repeatedly turning IGN ON/OFF | H36: 2 | I36: ▪ Repeat ACC & IGN ON/OFF quickly 20 times ▪ ACC & IGN ON ▪ Check recording status signal | J36: ▪ BLTN_CAM_RecSet_OWD = 0x1(OFF) | O36: X | P36: X | Q36: O
H37: 3 | I37: ▪ Check front/rear camera indicator | J37: ▪ F/R-CAM_INDI = OFF | O37: X | P37: X | Q37: X
H38: 4 | I38: ▪ Check EVENT_SW_INDI | J38: ▪ EVENT_SW_INDI = OFF | O38: X | P38: X | Q38: O
A39: OWD_005 | B39: SyR-FR-001,SyR-IF-001,SyR-NFR-001,SyR-FR-254,SyR-IF-064,SyR-FR-110,SEQ006 | C39: Requirement-based test | D39: Requirements Analysis Scenario-based Testing | E39: [Impact of continuous recording while driving] - (1) | F39: Checking the impact of simultaneous recording of other videos during driving recording | G39: ▪ Built-in Cam: Booted successfully ▪ Front/Rear Camera: Recognized by the system ▪ SD Card: Original installed and ready to store data ▪ DCM/CCU/CW: Connected and recognized by the system ▪ Vehicle Power: KEY ON ▪ Vehicle Voltage: 12V | H39: 1 | I39: ▪ Turn on Continuous Driving / Driving Event Recording Settings | J39: ▪ BLTN_CAM_RecSet_OWD = 0x2(ON) | O39: X | P39: X | Q39: O
H40: 2 | I40: ▪ AVN screen switching ▪ Start time-lapse recording (long press Event Switch) | J40: ▪ BLTN_CAM_RecSta TML = 0x1(Recording) | O40: X | P40: X | Q40: O
...

Sheet 주차 후 녹화 기능
A1: {="OWP_"&TEXT(MAX(IFERROR(--MID($A$2:$A$4966,5,3),0)),"000")} -> OWP_031 | E1: English Translation | F1: English Translation | G1: English Translation | I1: English Translation | J1: English Translation
A2: ID | B2: SyR ID | C2: Test method | D2: TC design method | E2: Name | F2: Description | G2: Precondition | H2: Step | I2: Test Procedure | J2: Expected Result | K2: Result | L2: Measure Value | M2: Remarks | O2: Manual (Basic) | P2: Automation (Basic) | Q2: Automation Applied | R2: Specification Category
A3: OWP_001 | B3: SyR-FR-002,SyR-IF-020,SyR-FR-052,SyR-FR-060,SyR-FR-065 | C3: ▪ Requirement-based test | D3: ▪ Requirements Analysis | E3: [Continuous Recording While Parked] : Check Initial Value | F3: Check initial values ​​for continuous parking recording settings | G3: ▪ Built-in Cam: Booted successfully ▪ Front/Rear Camera: Recognized by the system ▪ SD Card: Original installed and ready to store data ▪ DCM/CCU/CW: Connected and recognized by the system ▪ Vehicle Power: KEY ON ▪ Vehicle Voltage: 12V | H3: 1 | I3: ▪ ICUPowerAutoCutMode = 0x0(Factory mode) ▪ ICUPowerAutoCutMode = 0x2(Customer mode) ▪ CF_AVN_BLTN_CAM_USMReset = 0x1 (Built-in Cam USM Reset) signal transmission | J3: ▪ Check Initial Values : Always Parking OFF, Parking Event OFF, Event Notification ON | O3: X | P3: X | Q3: O | R3: 주차녹화_지원
H4: 2 | I4: ▪ Driving Continuous Recording Setting ON ▪ Transmit CF_AVN_BLTN_CAM_USMReset = 0x1(Built-in Cam USM Reset) signal | J4: ▪ BLTN_CAM_RecSet_OWP = 0x2(ON) : The default recording setting is ON when initializing after FRS setup. | O4: X | P4: X | Q4: O | R4: 주차녹화_지원
H5: 3 | I5: ▪ [Settings] - [Event Detection Sensitivity] - Check Recording While Parked | J5: ▪ BLTN_CAM_SenSet_PEV = 0x3(Lv.3) | O5: X | P5: X | Q5: O | R5: 주차녹화_지원
F6: Parking Continuous Recording Time Setting (~20Hr Specification) - Check Initial Value | H6: 4 | I6: ▪ [Record while parked] - [Record while parked] - Check default value | J6: ▪ BLTN_CAM_Set_PrkTime = 0xC(20Hr) | O6: O | P6: X | Q6: O | R6: 주차녹화_지원
F7: Confirmation of continuous parking recording operation | H7: 5 | I7: ▪ HU Mode Transition ▪ KEY OFF | J7: ▪ When transitioning to HU mode, BLTN_CAM_RecSta_OWD = 0x0 (OFF) ▪ When KEY OFF, BLTN_CAM_RecSta_OWP = 0x1 (Recording) : The difference between the actual recording start time (check recording file) and the signal ON must be within 2 seconds. | O7: O | P7: O | Q7: O | R7: 주차녹화_지원
H8: 6 | I8: ▪ Check front/rear camera indicator | J8: ▪ F/R-CAM_INDI = Blink - Blink Frequency: 0.5Hz(Duty : 50%) | O8: O | P8: X | Q8: X | R8: 주차녹화_지원
H9: 7 | I9: ▪ Check EVENT_SW_INDI | J9: ▪ EVENT_SW_INDI = ON | O9: O | P9: O | Q9: O | R9: 주차녹화_지원
A10: OWP_002 | B10: SyR-FR-002,SyR-IF-002,SyR-IF-040,SyR-FR-157,SyR-FR-114,SyR-NFR-058,SyR-FR-266,SyR-FR-265 | C10: ▪ Requirement-based test | D10: ▪ Requirements Analysis | E10: [Continuous Recording While Parked] Setting ON/OFF | F10: Check that the continuous parking recording setting is OFF. | G10: ▪ Built-in Cam: Booted successfully ▪ Front/Rear Camera: Recognized by the system ▪ SD Card: Original installed and ready to store data ▪ DCM/CCU/CW: Connected and recognized by the system ▪ Vehicle Power: KEY ON ▪ Vehicle Voltage: 12V | H10: 1 | I10: ▪ [Settings] - [Recording] - [Recording While Parked] - Turn off Continuous Recording | J10: ▪ BLTN_CAM_RecSet_OWP = 0x1(OFF) | O10: O | P10: O | Q10: O | R10: 주차녹화_지원
F11: Confirmation that continuous parking recording does not operate when recording settings are OFF | H11: 2 | I11: ▪ KEY OFF ▪ Check recording status signal | J11: ▪ BLTN_CAM_RecSta_OWP = 0x0(OFF) | O11: O | P11: O | Q11: O | R11: 주차녹화_지원
H12: 3 | I12: ▪ Check front/rear camera indicator | J12: ▪ F/R-CAM_INDI = OFF | O12: O | P12: X | Q12: X | R12: 주차녹화_지원
H13: 4 | I13: ▪ Check EVENT_SW_INDI | J13: ▪ EVENT_SW_INDI = OFF | O13: O | P13: O | Q13: O | R13: 주차녹화_지원
F14: Check BLTN_CAM_Prk_Oprable_Time | H14: 5 | I14: ▪ SOC Anomaly Status - SoC: No reception or Invalid (0x65~0xFE) or Error (0xFF) transmission ▪ [Settings] - [Recording] - [Recording While Parked] - Continuous Recording Setting ON ▪ KEY OFF | J14: ▪ BLTN_CAM_Prk_Oprable_Time = 0x00 | O14: X | P14: X | Q14: O | R14: 주차녹화_지원
F15: Confirm recording file creation (3 minutes) - Create 1 3-minute recording file | H15: 6 | I15: ▪ Built-in Cam Main Screen ▪ [Settings] - [Recording] - [Recording While Parked] - Continuous Recording Setting ON ▪ KEY OFF ▪ Wait 3 minutes, then KEY ON ▪ Return to Built-in Cam Main Screen and check the [Continuous Recording While Parked] storage box | J15: ▪ Verify that continuous recording files are saved while parked - Verify that a list containing 1 file (Front + Rear video, 3 min) is created ▪ There should be no issues with video distortion, black screens, noise, or color quality - The progress bar plays to the end during playback | O15: O | P15: X | Q15: X | R15: 주차녹화_지원
F16: [Conditions of Evil] ACC&IGN Quickly turn ON/OFF 20 times, then OFF | H16: 7 | I16: ▪ Quickly turn the key ON/OFF 20 times, then turn it OFF (Quickly press the actual vehicle engine start button) | J16: ▪ Start parking recording successfully ▪ Check if there are any unplayable recording files (check thumbnails as well) | O16: O | P16: X | Q16: O | R16: 주차녹화_지원
A17: OWP_003 | B17: SyR-FR-002,SyR-NFR-002,SyR-CON-036,SyR-FR-099,SyR-CON-037,SyR-FR-101,SyR-FR-102,SyR-FR-104,SyR-FR-105,SyR-FR-106,SyR-CON-039,SyR-NFR-058,SyR-FR-266,SyR-FR-265 | C17: ▪ Requirement-based test | D17: ▪ Requirements Analysis | E17: [Continuous Recording While Parked] : Full-time Recording | F17: Confirmation of recording file creation (20 hours) | G17: ▪ Built-in Cam: Booted successfully ▪ Front/Rear Camera: Recognized by the system ▪ SD Card: Original installed and ready to store data ▪ DCM/CCU/CW: Connected and recognized by the system ▪ Vehicle Power: KEY ON ▪ Vehicle Voltage: 12V | H17: 1 | I17: ▪ Turn off the key after setting continuous parking recording for 20 hours ▪ Continuous parking recording for 20 hours begins ▪ Turn the key on, enter the built-in cam screen, and check the continuous parking recording box | J17: ▪ Confirmation of continuous recording file saving while parked - Confirmation of creation of a list of 40 Front & Rear videos (30 minutes) | O17: X | P17: X | Q17: X | R17: 주차녹화_지원
F18: Check for interruptions in related actions during continuous recording | H18: 2 | I18: ▪ KEY OFF ▪ Maintain CAN Alive state by inputting NM signal ▪ Perform 20 hours of continuous parking recording ▪ Check BLTN_CAM_RecSta_OWP signal in CAN LOG after parking recording is complete | J18: ▪ The BLTN_CAM_RecSta_OWP signal will not be turned OFF at the time of individual file saving. | O18: X | P18: X | Q18: X | R18: 주차녹화_지원
F19: Confirmation of recording file creation (12 hours) | H19: 3 | I19: ▪ Turn off the key after setting continuous 12-hour recording for parking. ▪ Turn the key on, enter the built-in cam screen, and check the continuous parking storage box. | J19: ▪ Confirmation of continuous recording file saving while parked - Confirmation of creation of a list of 24 Front & Rear videos (30 minutes) | O19: X | P19: X | Q19: X | R19: 주차녹화_지원
F20: Confirmation of recording file creation (6 hours) | H20: 4 | I20: ▪ Turn off the key after setting continuous parking recording for 6 hours. ▪ Turn the key on, enter the built-in cam screen, and check the continuous parking recording box. | J20: ▪ Confirmation of continuous recording file saving while parked - Confirmation of creation of a list of 12 Front & Rear videos (30 minutes) | O20: X | P20: X | Q20: X | R20: 주차녹화_지원
F21: Confirmation of recording file creation (2 hours) | H21: 5 | I21: ▪ Turn off the key after setting continuous parking recording for 2 hours. ▪ Turn the key on, enter the built-in cam screen, and check the continuous parking recording box. | J21: ▪ Confirmation of continuous recording file saving while parked - Confirmation of creation of 4 lists for Front & Rear Video (30 min) | O21: X | P21: X | Q21: X | R21: 주차녹화_지원
F22: Separate group index when date changes during recording | H22: 6 | I22: ▪ Parking recording starts at 23:40 ▪ Check the parking recording video list after 3 recording files are created 1 hour later | J22: ▪ Created as 2 recording groups - 23:40:00 ~ 00:10:00 - 00:10:00 ~ 00:40:00 | O22: X | P22: X | Q22: X | R22: 주차녹화_지원
F23: Check recording file specifications | H23: 7 | I23: ▪ Check the generated recording file on the PC | J23: ▪ Video saving/playback frame rate: 2 FPS ▪ Resolution: 2980*1440 (QHD), No audio recording ▪ No video horizontal flip | O23: O | P23: X | Q23: X | R23: 주차녹화_지원
A24: OWP_004 | B24: SyR-FR-002,SyR-FR-009,SyR-FR-110 | C24: ▪ Requirement-based test | D24: ▪ Requirements Analysis | E24: [Continuous Recording While Parked] : Checking the Impact of Simultaneous Recording | F24: Verification of impact when recording other videos simultaneously during parking recording - Operation verification | G24: ▪ Built-in Cam: Booted successfully ▪ Front/Rear Camera: Recognized by the system ▪ SD Card: Original installed and ready to store data ▪ DCM/CCU/CW: Connected and recognized by the system ▪ Vehicle Power: KEY ON ▪ Vehicle Voltage: 12V | H24: 1 | I24: ▪ Parking Always On / Parking Event Setting ON ▪ Parking Recording Starts After Key Off ▪ Enable Switch Event ▪ Enable Impact Event ▪ 1-Minute Standby ▪ Built-in Cam Main Screen | J24: ▪ BLTN_CAM_RecSet_OWP = 0x2(ON) ▪ F/R-CAM_INDI No issues ▪ EVENT_SW_INDI No issues | O24: X | P24: X | Q24: O | R24: 주차녹화_지원
F25: Checking the impact of simultaneous recording of other videos during parking recording - Video verification | H25: 2 | I25: ▪ [Always check while parked] Check locker | J25: ▪ Confirmation of continuous recording file saving while parked - Confirmation of front & rear video (60 sec) list creation | O25: X | P25: X | Q25: X | R25: 주차녹화_지원
A26: OWP_005 | B26: SyR-FR-002,SyR-FR-256,SEQ003 | C26: ▪ Requirement-based test | D26: ▪ Requirements Analysis | E26: [Continuous Recording While Parked] : When camera video is not input | F26: Front camera removal, parking recording + manual/impact events | G26: ▪ Built-in Cam: Booted successfully ▪ Front/Rear Camera: Recognized by the system ▪ SD Card: Original installed and ready to save ▪ DCM/CCU/CW: Connected and recognized by the system ▪ Vehicle Power: KEY ON ▪ Vehicle Voltage: 12V ▪ Settings: Parking Recording / Parking Event Settings ON | H26: 1 | I26: ▪ Start parking recording after turning off the key ▪ Remove front camera after waiting 30 seconds ▪ Reinstall camera after waiting 20 seconds ▪ Mandate impact event manually ▪ Turn key on after waiting 30 seconds to check the generated recording file | J26: ▪ Recorded video file created (Black screen recorded if no video input) ▪ Camera restored to normal after installation | O26: X | P26: X | Q26: X | R26: 주차녹화_지원
F27: Rearview camera removal, parking recording + manual/impact events | H27: 2 | I27: ▪ Start parking recording after turning off the key ▪ Remove rear camera after waiting 30 seconds ▪ Reinstall camera after waiting 20 seconds ▪ Mandate impact event manually ▪ Turn key on after waiting 30 seconds to check the generated recording file | J27: ▪ Continuous recording, impact video file generated (black screen recording if no video input) ▪ Camera returns to normal after installation | O27: X | P27: X | Q27: X | R27: 주차녹화_지원
F28: Front/rear camera removal, constant parking + manual/impact events | H28: 3 | I28: ▪ Start parking recording after turning off the key ▪ Remove front and rear cameras after waiting 30 seconds ▪ Reinstall cameras after waiting 20 seconds ▪ Mandate impact event manually ▪ Wait 30 seconds, turn the key on to check the generated recording file | J28: ▪ Recorded video file created (Black screen recorded if no video input) ▪ Camera restored to normal after installation | O28: X | P28: X | Q28: X | R28: 주차녹화_지원
F29: When attaching/detaching the front camera during parking recording | H29: 4 | I29: ▪ Start parking recording after turning off the key ▪ Detach the front camera while parking recording is in progress ▪ Wait 30 seconds, then turn the key on to check the generated recording file | J29: ▪ Recorded video file created (Black screen recorded if no video input) ▪ Camera restored to normal after installation (Recorded video plays normally) ▪ No recording of impact events occurred ▪ CAN communication maintained normal | O29: X | P29: X | Q29: X | R29: 주차녹화_지원
F30: When attaching or detaching the rear camera during parking recording | H30: 5 | I30: ▪ Start parking recording after turning off the key ▪ Detach the rear camera while parking recording is in progress ▪ Wait 30 seconds, then turn the key on to check the generated recording file | J30: ▪ Recorded video file created (Black screen recorded if no video input) ▪ Camera restored to normal after installation (Recorded video plays normally) ▪ No recording of impact events occurred ▪ CAN communication maintained normal | O30: X | P30: X | Q30: X | R30: 주차녹화_지원
F31: When removing the camera during parking recording and reinstalling it after turning the KEY ON | H31: 6 | I31: ▪ Start parking recording after Key Off ▪ Network Sleep ▪ Remove front/rear cameras ▪ Turn Key On ▪ Enter built-in cam mode for real-time view ▪ Install front/rear cameras | J31: ▪ Camera restored to normal after installation (real-time screen) | O31: X | P31: X | Q31: X | R31: 주차녹화_지원
H32: 7 | I32: ▪ Built-in Cam Settings - Change Display Angle : Front/Rear -5 ~ +5 Value Setting | J32: ▪ Angle set from -5 to +5 depending on front/rear setting values | O32: X | P32: X | Q32: X | R32: 주차녹화_지원
F33: Check G-sensor operation after attaching/detaching the camera during parking recording | H33: 8 | I33: ▪ Turn app notifications ON ▪ Turn KEY OFF to start parking recording ▪ Wait 30 seconds, then remove front camera ▪ Wait 20 seconds, then reattach camera ▪ Enter impact event | J33: ▪ Recorded video file created (Black screen recording if no video input) ▪ Camera restored to normal within 2 seconds after installation (Recorded file driving data, capacity, playback time) ▪ Confirmed saving of impact event recording ▪ Confirmed operation of impact event notification : BLTN_CAM_PEV_Recorded = 0x2(Park Event Recorded) up to 5 times | O33: X | P33: X | Q33: X | R33: 주차녹화_지원
H34: 9 | I34: ▪ ↑ Verify that the above procedure is repeated 10 times | J34: ▪ Recorded video file created (Black screen recording if no video input) ▪ Camera restored to normal within 2 seconds after installation (Recorded file driving data, capacity, playback time) ▪ Confirmation of impact event recording saved | O34: X | P34: X | Q34: X | R34: 주차녹화_지원
A35: OWP_006 | B35: SyR-FR-253,SyR-FR-255 | C35: ▪ Requirement-based test ▪ Performance test | D35: ▪ Requirements Analysis ▪ Decision Table Testing | E35: [Power Fail Safety Operation] : Emergency Power (Super Cap) Performance (Parking) | F35: Continuous recording while parked | G35: ▪ Built-in Cam: Booted successfully ▪ Front/Rear Camera: Recognized by system ▪ SD Card: Original installed and ready to store ▪ DCM/CCU/CW: Connected and recognized by system ▪ Vehicle Power: KEY ON ▪ Vehicle Voltage: 12V ▪ Settings: Always Parking / Parking Event Setting ON | H35: 1 | I35: ▪ KEY OFF ▪ Continuous video recording while parked ▪ Disconnect main connector ▪ Wait 30 seconds, then turn KEY ON to check the generated recording file | J35: ▪ The file being recorded right before power is turned off is saved. ※ Based on settings, at least two files must be saved. - Save Priority: Always > Impact Detection Save (Event) > Manual Save | O35: X | P35: X | Q35: X | R35: 주차녹화_지원
F36: Recording event (impact) while parked | H36: 2 | I36: ▪ KEY OFF ▪ Record video of impact event while parked ▪ Disconnect main connector (immediately after impact event) ▪ Wait 30 seconds, then turn KEY ON to check the generated recording file | J36: ▪ The file being recorded right before power is turned off is saved. ※ Based on settings, at least two files must be saved. - Save Priority: Always > Impact Detection Save (Event) > Manual Save | O36: X | P36: X | Q36: X | R36: 주차녹화_지원
F37: Recording event (switch) while parked | H37: 3 | I37: ▪ KEY OFF ▪ Record video of the parked event switch ▪ Disconnect the main connector (immediately after the switch event occurs) ▪ Wait 30 seconds, then turn the KEY ON to check the generated recording file | J37: ▪ The file being recorded right before power is turned off is saved. ※ Based on settings, at least two files must be saved. - Save Priority: Always > Impact Detection Save (Event) > Manual Save | O37: X | P37: X | Q37: X | R37: 주차녹화_지원
F38: Simultaneous execution of parking, constant, impact, and manual events | H38: 4 | I38: ▪ KEY OFF ▪ Record Event Switch Video & Impact Video while Parked ▪ Disconnect Main Connector (Immediately after event) ▪ Wait 30 seconds, then turn KEY ON to check the generated recording file | J38: ▪ The file being recorded right before power is turned off is saved. ※ Based on settings, at least two files must be saved. - Save Priority: Always > Impact Detection Save (Event) > Manual Save | O38: O | P38: X | Q38: X | R38: 주차녹화_지원
F39: B+ OFF during continuous recording while parked | H39: 5 | I39: ▪ KEY OFF ▪ Continuous parking video recording, rear camera not recognized ▪ Disconnect main connector ▪ Wait 30 seconds, then turn KEY ON to check the generated recording file | J39: ▪ The file being recorded right before power is turned off is saved. ※ Based on settings, at least two files must be saved. - Save Priority: Always > Impact Detection Save (Event) > Manual Save | O39: X | P39: X | Q39: X | R39: 주차녹화_지원
A40: OWP_007 | B40: SyR-FR-005,SEQ002,SEQ004 | C40: ▪ Requirement-based test | D40: ▪ Requirements Analysis | E40: [Recording Event Impacts While Parked] : Check Initial Value | F40: Check initial value | G40: ▪ Built-in Cam: Booted successfully ▪ Front/Rear Camera: Recognized by the system ▪ SD Card: Original installed and ready to store data ▪ DCM/CCU/CW: Connected and recognized by the system ▪ Vehicle Power: KEY ON ▪ Vehicle Voltage: 12V | H40: 1 | I40: ▪ ICUPowerAutoCutMode = 0x0(Factory mode) ▪ ICUPowerAutoCutMode = 0x2(Customer mode) ▪ [CW Settings] - [General] - [Reset] - [Delete Guest Profile/System Reset] | J40: ▪ Check Initial Values - Always Parking OFF, Parking Event OFF, Event Notification ON | O40: X | P40: X | Q40: O | R40: 주차녹화_지원
...

Sheet HU 연동기능
A1: {="HU_"&TEXT(MAX(IFERROR(--MID($A$2:$A$4842,5,3),0)),"000")} -> HU_050 | E1: English Translation | F1: English Translation | G1: English Translation | I1: English Translation | J1: English Translation
A2: ID | B2: SyR ID | C2: Test method | D2: TC design method | E2: Name | F2: Description | G2: Preconfition | H2: Step | I2: Test Procedure | J2: Expected Result | K2: Result | L2: Measure Value | M2: Remarks | O2: Manual (Basic) | P2: Automation (Basic) | Q2: Automation Applied | R2: Specification Category
A3: HU_001 | B3: SyR-IF-031,SyR-FR-088,SyR-FR-089,SEQ001 | C3: ▪Requirement-based test ▪Test of interaction/ communication | D3: ▪Requirements Analysis ▪Interface Analysis ▪State Transition Testing | E3: [Built-in Cam Screen Mode] (1) | F3: Built-in Cam Mode Video Output Confirmation | G3: ▪ Built-in Cam: Booted successfully ▪ Front/Rear Camera: Recognized by the system ▪ SD Card: Original installed and ready to save ▪ DCM/CCU/CW: Connected and recognized by the system ▪ Vehicle Power: KEY ON ▪ Vehicle Voltage: 12V ▪ Recording Settings: Driving Continuous/Event, Parking Continuous/Event Settings ON | H3: 1 | I3: ▪ AVN Mode Status ▪ Touch Built-in Cam Menu Icon (BLTN_CAM_LVDS_Mode_Cmd = 0x0:Front and Rear Camera) ▪ Touch Real-time Screen ▪ Go Back ▪ Confirm Repeat 10 times | J3: ▪ BLTN_CAM_LVDS_Mode_State = 0x0: Front and Rear Camera : LVDS video output switching time within 2 seconds (Approximately +1 second can be expected as the CW generates the GUI) ▪ Confirmed normal output of video list thumbnails | O3: O | P3: X | Q3: X
F4: Check BLTN_CAM mode entry signal | H4: 2 | I4: ▪ Touch the Built-In Cam screen entry button (HU_BLTN_CAM_UI_Mode = 0x1 : Built-In Cam Mode) | J4: ▪ BLTN_CAM_HU_UI_Mode (0x0: HU UI mode) → invalid → (0x2: Preparing BLTN_CAM Mode) → invalid → (0x1:BLTN_CAM mode) | O4: O | P4: X | Q4: O
F5: Transition to AVN mode by turning the KEY OFF while in BLTN_CAM mode | H5: 3 | I5: ▪ Turn KEY OFF while in Built-in Cam mode -'BLTN_CAM_UI_Mode_Tmt_Req signal not transmitted confirmed | J5: ▪ BLTN_CAM_HU_UI_Mode (0x1:BLTN_CAM mode) → invalid → (0x0: HU UI mode) → invalid → (0x0: HU UI mode) | O5: O | P5: X | Q5: O
F6: AVN mode transition via AVN mode signal | H6: 4 | I6: ▪ KEY ON ▪ Touch the built-in cam screen entry button ▪ Touch the Home/Back/CW physical buttons (HU_BLTN_CAM_UI_Mode = 0x0 : HU UI Mode) | J6: ▪ BLTN_CAM_HU_UI_Mode (0x1:BLTN_CAM mode) → invalid → (0x0: HU UI mode) | O6: O | P6: X | Q6: O
F7: AVN mode ↔ BLTN_CAM mode | H7: 5 | I7: ▪ Touch the built-in cam screen entry button ▪ Touch the Home button (repeat quickly 10 times) | J7: ▪ If in AVN mode after repeatedly entering and exiting Built-in Cam mode: Driving recording starts normally (without delay) ▪ If in Built-in Cam mode: Driving recording is OFF, and recorded video will play back normally | O7: O | P7: X | Q7: X
F8: Exiting BLTN_CAM mode midway | H8: 6 | I8: ▪ Touch the built-in cam screen entry button ▪ Touch the CW Home button on the screen transition loading screen (confirm by repeating 10 times) | J8: ▪ Start driving recording immediately when the repetitive action stops | O8: X | P8: X | Q8: O
F9: Attempting to quickly enter built-in cam mode during boot-up | H9: 7 | I9: ▪ ACC & IGN ON ▪ Quickly and continuously tap the Built-in Cam mode entry icon | J9: ▪ Enter Built-in Cam mode after booting is complete (enter within 2 seconds of booting complete) ▪ Driving recording will begin when the Back button is touched (1 second after exiting Built-in Cam mode) | O9: X | P9: X | Q9: O
F10: Condition preventing entry into Built-in Cam mode: During booting | H10: 8 | I10: ▪ Built-in Cam B+ Reset | J10: ▪ Outputs 0xD until Built-in Cam boot is complete, 0x0 after completion ▪ BLTN_CAM_HU_UI_Mode invalid → (0xD : Built-in CAM not Ready to be HU UI Mode) → invalid → (0x0: HU UI mode) | O10: X | P10: X | Q10: X
H11: 9 | I11: ▪ Enter Built-in Cam mode after Built-in Cam has finished booting | J11: ▪ BLTN_CAM_HU_UI_Mode (0x0: HU UI mode) → invalid → (0x2: Preparing BLTN_CAM Mode) → invalid → (0x1:BLTN_CAM mode) | O11: X | P11: X | Q11: X
F12: Conditions under which Built-in Cam Mode cannot be entered (Parking Recording) : Sleep → KEY ON | H12: 10 | I12: ▪ KEY ON ▪ Parking Recording in Progress (Network Sleep State) ▪ Inject NM signal to wake up the network | J12: ▪ BLTN_CAM_HU_UI_Mode = 0xD: Built-in CAM not Ready to be HU UI Mode | O12: X | P12: X | Q12: O
H13: 11 | I13: ▪ KEY ON | J13: ▪ Outputs 0xD until Built-in Cam boot complete, 0x0 after completion ▪ BLTN_CAM_HU_UI_Mode (0xD: Built-in CAM not Ready to be HU UI Mode) → invalid → (0x0: HU UI mode) | O13: X | P13: X | Q13: O
H14: 12 | I14: ▪ Enter Built-in Cam Mode ▪ Turn on Parking Motion Recording Settings | J14: ▪ BLTN_CAM_HU_UI_Mode (0x0: HU UI mode) → invalid → (0x2: Preparing BLTN_CAM Mode) → invalid → (0x1:BLTN_CAM mode) | O14: X | P14: X | Q14: O
F15: Conditions under which Built-in Cam mode cannot be entered (Parking Motion Recording) : Sleep → KEY ON | H15: 13 | I15: ▪ KEY OFF ▪ Parking motion recording in progress (Network Sleep state) ▪ Network wake up by injecting NM signal | J15: ▪ BLTN_CAM_HU_UI_Mode = 0xD: Built-in CAM not Ready to be HU UI Mode | O15: X | P15: X | Q15: O
H16: 14 | I16: ▪ KEY ON | J16: ▪ Outputs 0xD until Built-in Cam boot complete, 0x0 after completion ▪ BLTN_CAM_HU_UI_Mode (0xD: Built-in CAM not Ready to be HU UI Mode) → invalid → (0x0: HU UI mode) | O16: X | P16: X | Q16: O
H17: 15 | I17: ▪ Enter Built-in Cam Mode | J17: ▪ BLTN_CAM_HU_UI_Mode (0x0: HU UI mode) → invalid → (0x2: Preparing BLTN_CAM Mode) → invalid → (0x1:BLTN_CAM mode) | O17: X | P17: X | Q17: O
F18: Confirm text output when entering Built-in Cam mode | H18: 16 | I18: ▪ Enter Built-in Cam Mode | J18: ▪ Print legal notice text | O18: X | P18: X | Q18: X
A19: HU_002 | B19: SyR-IF-031,SyR-FR-089 | C19: ▪Requirement-based test | D19: ▪Requirements Analysis | E19: [Built-in Cam Screen Mode] (2) Undefined value | F19: HS-CAN: [HU_BLTN_CAM_PE_00_200ms] - HU_UI_Mode = Reserved B2-FD: [BLTN_CAM_FD_HU_01_200ms] - HU_UI_Mode = Reserved | G19: ▪ Built-in Cam: Booted successfully ▪ Front/Rear Camera: Recognized by the system ▪ SD Card: Original installed and ready to save ▪ DCM/CCU/CW: Connected and recognized by the system ▪ Vehicle Power: KEY ON ▪ Vehicle Voltage: 12V ▪ Recording Settings: Driving Continuous/Event, Parking Continuous/Event Settings ON | H19: 1 | I19: ▪ [HU_BLTN_CAM_PE_00_200ms] - HU_BLTN_CAM_UI_Mode = 0x3 (Reserved) | J19: ▪ BLTN_CAM_HU_UI_Mode maintains previous state | O19: X | P19: X | Q19: O
H20: 2 | I20: ▪ [HU_BLTN_CAM_PE_00_200ms] - HU_BLTN_CAM_UI_Mode = 0x4 (Reserved) | J20: ▪ BLTN_CAM_HU_UI_Mode maintains previous state | O20: X | P20: X | Q20: O
H21: 3 | I21: ▪ [HU_BLTN_CAM_PE_00_200ms] - HU_BLTN_CAM_UI_Mode = 0x5 (Reserved) | J21: ▪ BLTN_CAM_HU_UI_Mode maintains previous state | O21: X | P21: X | Q21: O
H22: 4 | I22: ▪ [HU_BLTN_CAM_PE_00_200ms] - HU_BLTN_CAM_UI_Mode = 0x6 (Reserved) | J22: ▪ BLTN_CAM_HU_UI_Mode maintains previous state | O22: X | P22: X | Q22: O
H23: 5 | I23: ▪ [HU_BLTN_CAM_PE_00_200ms] - HU_BLTN_CAM_UI_Mode = 0x7 (Reserved) | J23: ▪ BLTN_CAM_HU_UI_Mode maintains previous state | O23: X | P23: X | Q23: O
H24: 6 | I24: ▪ [HU_BLTN_CAM_PE_00_200ms] - HU_BLTN_CAM_UI_Mode = 0x8 (Reserved) | J24: ▪ BLTN_CAM_HU_UI_Mode maintains previous state | O24: X | P24: X | Q24: O
H25: 7 | I25: ▪ [HU_BLTN_CAM_PE_00_200ms] - HU_BLTN_CAM_UI_Mode = 0x9 (Reserved) | J25: ▪ BLTN_CAM_HU_UI_Mode maintains previous state | O25: X | P25: X | Q25: O
H26: 8 | I26: ▪ [HU_BLTN_CAM_PE_00_200ms] - HU_BLTN_CAM_UI_Mode = 0xA (Reserved) | J26: ▪ BLTN_CAM_HU_UI_Mode maintains previous state | O26: X | P26: X | Q26: O
H27: 9 | I27: ▪ [HU_BLTN_CAM_PE_00_200ms] - HU_BLTN_CAM_UI_Mode = 0xB (Reserved) | J27: ▪ BLTN_CAM_HU_UI_Mode maintains previous state | O27: X | P27: X | Q27: O
H28: 10 | I28: ▪ [HU_BLTN_CAM_PE_00_200ms] - HU_BLTN_CAM_UI_Mode = 0xC (Reserved) | J28: ▪ BLTN_CAM_HU_UI_Mode maintains previous state | O28: X | P28: X | Q28: O
H29: 11 | I29: ▪ [HU_BLTN_CAM_PE_00_200ms] - HU_BLTN_CAM_UI_Mode = 0xD (Reserved) | J29: ▪ BLTN_CAM_HU_UI_Mode maintains previous state | O29: X | P29: X | Q29: O
H30: 12 | I30: ▪ [HU_BLTN_CAM_PE_00_200ms] - HU_BLTN_CAM_UI_Mode = 0xE (Reserved) | J30: ▪ BLTN_CAM_HU_UI_Mode maintains previous state | O30: X | P30: X | Q30: O
F31: HS-CAN: [HU_BLTN_CAM_PE_00_200ms] - HU_UI_Mode = INVALID B2-FD: [BLTN_CAM_FD_HU_01_200ms] - HU_UI_Mode = INVALID | H31: 13 | I31: ▪ [HU_BLTN_CAM_PE_00_200ms] - HU_BLTN_CAM_UI_Mode = 0xF(Invalid) | J31: ▪ BLTN_CAM_HU_UI_Mode maintains previous state | O31: X | P31: X | Q31: O
A32: HU_003 | B32: SyR-IF-031,SyR-FR-089 | C32: ▪Requirement-based test ▪Test of interaction/ communication | D32: ▪Requirements Analysis ▪Interface Analysis | E32: [Built-in Cam Screen Mode] (3) Power Conditions | F32: ACC → Enter Built-in Cam View → IGN → Maintain Built-in Cam View | G32: ▪ Built-in Cam: Booted successfully ▪ Front/Rear Camera: Recognized by the system ▪ SD Card: Original installed and ready to save ▪ DCM/CCU/CW: Connected and recognized by the system ▪ Vehicle Power: KEY OFF ▪ Vehicle Voltage: 12V ▪ Recording Settings: Driving Continuous/Event, Parking Continuous/Event Settings ON | H32: 1 | I32: ▪ ACC ON ▪ Enter Built-in Cam Screen | J32: ▪ Enter BLTN_CAM mode | O32: X | P32: O | Q32: O
H33: 2 | I33: ▪ IGN ON ▪ Check built-in cam screen retention | J33: ▪ Maintain BLTN_CAM mode | O33: X | P33: O | Q33: O
F34: IGN → Enter built-in cam view | H34: 3 | I34: ▪ ACC & IGN ON ▪ HU_UI_Mode = 0x1 (Built-In Cam Mode) | J34: ▪ Enter BLTN_CAM mode | O34: X | P34: X | Q34: O
F35: Remote Start Status → Enter Built-in Cam Screen | H35: 4 | I35: ▪ IGN ON (ACC OFF, Communication Alive) ▪ HU_UI_Mode = 0x1 (Built-In Cam Mode) | J35: ▪ Don't Care (In the actual vehicle, the AVN boots up but the screen is OFF) | O35: X | P35: X | Q35: X
F36: Remote Start → ACC ON → Enter Built-in Cam Screen | H36: 5 | I36: ▪ IGN ON ▪ Turn ACC ON after a 10-second wait ▪ HU_UI_Mode = 0x1(Built-In Cam Mode) | J36: ▪ Enter BLTN_CAM mode | O36: X | P36: X | Q36: O
F37: Repeat KEY ON/OFF 20 times | H37: 6 | I37: ▪ Key On, Driving/Parking Continuous Recording Setting On ▪ Enter AVN Mode ▪ Confirm Driving Recording In Progress ▪ Repeat Key Reset 20 times, then return to the final state Key On | J37: ▪ Enter BLTN_CAM mode | O37: X | P37: X | Q37: O
A38: HU_004 | B38: SyR-IF-080,SyR-CON-027 | C38: ▪Requirement-based test ▪Test of interaction/ communication | D38: ▪Requirements Analysis ▪Interface Analysis ▪Boundary Value Analysis | E38: [Built-in Cam Time Setting] (1) | F38: [HU_CLOCK_PE_02] Check RTC settings via message ▪ Verify if the current time is set (applied when the second value differs from the previous value) ▪ Verify if the time changes between 12-hour and 24-hour formats ※ In CAN specifications, if even one value is invalid, it is ignored. ※ In Ethernet specifications, refer only to the values ​​under the setting failure conditions below. ※ Signal preconditions by platform type HS-CAN : [HU_CLOCK_PE_02] B2-FD : [HU_CLOCK_01_1000ms] | G38: ▪ Built-in Cam: Booted successfully ▪ Front/Rear Camera: Recognized by the system ▪ SD Card: Original installed and ready to save ▪ DCM/CCU/CW: Connected and recognized by the system ▪ Vehicle Power: KEY ON ▪ Vehicle Voltage: 12V ▪ Recording Settings: Driving Continuous/Event, Parking Continuous/Event Settings ON | H38: 1 | I38: ▪ Driving Recording Setting ON, Recorded Video Time Information Display ON ▪ [HU_CLOCK_PE_02] - HU_TimeFormat = 0x2(24Hour) - HU_Status = 0x2(GPS receiving) - HU_TimeSetting = 0x1(User Time) - HU_DisplayHour = Set Current Time - HU_DisplayMinute = Set Current Time - HU_DisplaySecond = Set Current Time - HU_DisplayYear1 = Set Current Time - HU_DisplayMonth = Set Current Time - HU_DisplayYear2 = Set Current Time - HU_DisplayDay = Set Current Time - HU_ClockInfo = 0x1(ACLOCK Refresh) - HU_ComRefresh = 0x2(Internal Clock Exist) - HU_AM_PM_INFO = 0x0(Not Used) ▪ Built-in Cam Screen Enter ▪ Check the time on the clock at the top | J38: ▪ Match setting time: HH:MM ▪ 24-hour format display ▪ Check date: Month D (Day of the week) | O38: O | P38: X | Q38: X
H39: 2 | I39: ▪ Check export region time indication ※ Specifications verification required. | J39: ? | O39: X | P39: X | Q39: X
H40: 3 | I40: ▪ Check the day of the week display on the clock at the top center. | J40: ▪ Exactly matches the position and shape of the top clock on the AVN | O40: X | P40: X | Q40: X
...

Sheet 보조배터리 연동기능
A1: {="BAT_"&TEXT(MAX(IFERROR(--MID($A$2:$A$4534,5,3),0)),"000")} -> BAT_059 | E1: English Translation | F1: English Translation | G1: English Translation | I1: English Translation | J1: English Translation
A2: ID | B2: SyR ID | C2: Test method | D2: TC design method | E2: Name | F2: Description | G2: Precondition | H2: Step | I2: Test procedure | J2: Expect Result | K2: Result | L2: Measure Value | M2: Remarks | O2: Manual (Basic) | P2: Automation (Basic) | Q2: Automation Applied | R2: Specification Category
A3: BAT_012 | B3: SyR-FR-186,SyR-CON-048,SyR-IF-035 | C3: ▪Requirement-based test | D3: ▪Eqivalence Class Partitioning | E3: [July 2023 Business Update] Recording time available during parking recording updated | F3: Decrease if more than 1 hour remains | G3: ▪ Built-in Cam: Booted successfully ▪ Front/Rear Camera: Recognized by the system ▪ SD Card: Original installed and ready to save ▪ DCM/CCU/CW: Connected and recognized by the system ▪ Vehicle Power: KEY ON ▪ Vehicle Voltage: 12V ▪ Recording Settings: Driving Continuous/Event, Parking Continuous/Event Settings ON | H3: 1 | I3: ▪ Start 20-hour weekly recording ▪ Randomly wake up the network every hour (using CANoe CAPL) ▪ Check weekly recording availability time (BLTN_CAM_Prk_Oprable_Time) and then check for sleep. | J3: ▪ Updates and outputs the current remaining recording time upon Wake Up : BLTN_CAM_Prk_Oprable_Time = Remaining Time (rounded down to the nearest hour) | O3: X | P3: X | Q3: O | R3: 주차녹화_지원
F4: Round up if less than 1 hour remains | H4: 2 | I4: ↑ Continue by checking when there are 59 minutes remaining | J4: ▪ BLTN_CAM_Prk_Oprable_Time = 1 Hr | O4: X | P4: X | Q4: O | R4: 주차녹화_지원
A5: BAT_013 | B5: SyR-FR-186 | C5: ▪Requirement-based test | D5: ▪Requirements Analysis | E5: [BLTN_CAM_STAT_PE_00_200ms] BLTN_CAM_Prk_Oprable_Time - CCS function | F5: Operable time updated upon network wake-up during parking recording | G5: ▪ Built-in Cam: Booted successfully ▪ Front/Rear Camera: Recognized by the system ▪ SD Card: Original installed and ready to save ▪ DCM/CCU/CW: Connected and recognized by the system ▪ Vehicle Power: KEY ON ▪ Vehicle Voltage: 12V ▪ Recording Settings: Driving Continuous/Event, Parking Continuous/Event Settings ON | H5: 1 | I5: ▪ Start continuous parking recording (capable of recording for 2 hours or more) ▪ Network Wake-up by inputting a CAN signal after CAN Sleep ▪ Check BLTN_CAM_Prk_Oprable_Time signal value | J5: ▪ Output the BLTN_CAM_Prk_Oprable_Time value as is at the time of KEY OFF. | O5: X | P5: O | Q5: O | R5: 주차녹화_지원
F6: Operable time updated upon Network Wake-up during parking recording (after 1 hour) | H6: 2 | I6: ▪ Start continuous parking recording (capable of recording for 2 hours or more) ▪ Network Wake-up by inputting an arbitrary CAN signal after 1 hour of recording ▪ Check BLTN_CAM_Prk_Oprable_Time signal value | J6: ▪ Output the value of BLTN_CAM_Prk_Oprable_Time minus 1 hour at the time of KEY OFF. | O6: X | P6: X | Q6: O | R6: 주차녹화_지원
F7: Operable time updated upon network wake-up after parking recording is complete | H7: 3 | I7: ▪ Start continuous parking recording (capable of recording for 2 hours or more) ▪ Network Wake-up by inputting an arbitrary CAN signal after 1 hour of recording is complete ▪ Check BLTN_CAM_Prk_Oprable_Time signal value | J7: ▪ BLTN_CAM_Prk_Oprable_Time = 1 Hr output | O7: X | P7: X | Q7: O | R7: 주차녹화_지원
A8: BAT_014 | B8: SyR-FR-181,SyR-FR-186 | C8: ▪Requirement-based test | D8: ▪Requirements Analysis | E8: [BLTN_CAM_STAT_PE_00_200ms] BLTN_CAM_Prk_Oprable_Time - CCS function | F8: Check available parking recording time via the CCS app - Continuous parking recording | G8: ▪ Built-in Cam: Booted successfully ▪ Front/Rear Camera: Recognized by the system ▪ SD Card: Original installed and ready to save ▪ DCM/CCU/CW: Connected and recognized by the system ▪ Vehicle Power: KEY ON ▪ Vehicle Voltage: 12V ▪ Recording Settings: Driving Continuous/Event, Parking Continuous/Event Settings ON | H8: 1 | I8: ▪ Start continuous recording for 2 hours ▪ Network Wake-up by inputting an arbitrary CAN signal after completing recording for 1 hour or more ▪ Check BLTN_CAM_Prk_Oprable_Time signal value | J8: ▪ Output BLTN_CAM_Prk_Oprable_Time = 0x1 (Specification: 1 second ~ 1 hour 59 minutes 59 seconds → 1 hour output) | O8: X | P8: X | Q8: X | R8: 주차충격 알림_지원
H9: 2 | I9: ▪ Check the BLTN_CAM_Prk_Oprable_Time signal value after completing 2 hours of parking recording. | J9: ▪ BLTN_CAM_Prk_Oprable_Time = 0x0 output (Specification: 0 seconds (recording ends) → 0 hours output) | O9: X | P9: X | Q9: X | R9: 주차충격 알림_지원
A10: BAT_015 | B10: SyR-FR-181,SyR-FR-186 | C10: ▪Requirement-based test | D10: ▪Requirements Analysis | F10: Check available parking recording time via CCS app - Parking motion recording | G10: ▪ Built-in Cam: Booted successfully ▪ Front/Rear Camera: Recognized by the system ▪ SD Card: Original installed and ready to save ▪ DCM/CCU/CW: Connected and recognized by the system ▪ Vehicle Power: KEY ON ▪ Vehicle Voltage: 12V ▪ Recording Settings: Driving Continuous/Event, Motion/Event Settings ON | H10: 1 | I10: ▪ Start parking motion recording ▪ Network Wake-up by inputting an arbitrary CAN signal after recording for 1 hour or more is complete ▪ Check BLTN_CAM_Prk_Oprable_Time signal value | J10: ▪ P-LBM Model (LX3) : Output recording time based on SOC ▪ eAGM Model / P-LBM + eAGM Model (JW1 PE) : BLTN_CAM_Prk_Oprable_Time = BLTN_CAM_Set_PrkTime - BLTN_CAM_PRK_Oped_Time | O10: X | P10: X | Q10: X | R10: 주차충격 알림_지원
H11: 2 | I11: ▪ Check BLTN_CAM_Prk_Oprable_Time signal value after 2 hours of parking recording | J11: ▪ P-LBM Model (LX3) : Output recording time based on SOC ▪ eAGM Model / P-LBM + eAGM Model (JW1 PE) : BLTN_CAM_Prk_Oprable_Time = BLTN_CAM_Set_PrkTime - BLTN_CAM_PRK_Oped_Time | O11: X | P11: X | Q11: X | R11: 주차충격 알림_지원
A12: BAT_016 | B12: SyR-FR-181,SyR-IF-035,SyR-CON-040 | C12: ▪Requirement-based test | D12: ▪Requirements Analysis | E12: [BLTN_CAM_STAT_PE_00_200ms] BLTN_CAM_Prk_Oprable_Time_Max | F12: Check BLTN_CAM_Prk_Oprable_Time_Max output value (120 hours - always-on setting) | G12: ▪ Built-in Cam: Booted successfully ▪ Front/Rear Camera: Recognized by the system ▪ SD Card: Original installed and ready to save ▪ DCM/CCU/CW: Connected and recognized by the system ▪ Vehicle Power: KEY ON ▪ Vehicle Voltage: 12V ▪ Recording Settings: Driving Continuous/Event, Parking Continuous/Event Settings ON | H12: 1 | I12: ▪ Set parking recording time to 10–120 hours and check the signal below ▪ Check the BLTN_CAM_Prk_Oprable_Time_Max value | J12: ▪ BLTN_CAM_Prk_Oprable_Time_Max = 0x78(120Hr) Fixed | O12: X | P12: O | Q12: O | R12: 주차녹화_지원
